<?xml version="1.0" ?>
<!-- =================================================================================== -->
<!-- |    This document was autogenerated by xacro from /home/terminator0117/ws_moveit/src/lynxmotion_al5d_description/urdf/lynxmotion_al5d.xacro | -->
<!-- |    EDITING THIS FILE BY HAND IS NOT RECOMMENDED                                 | -->
<!-- =================================================================================== -->
<robot name="lynxmotion_al5d">
    <!-- Include materials -->
    <material name="Black">
        <color rgba="0.0 0.0 0.0 1.0" />
    </material>
    <material name="Green">
        <color rgba="0.0 1.0 0.0 1.0" />
    </material>
    <material name="white">
        <color rgba="1 1 1 1" />
    </material>
    <material name="Silver">
        <color rgba="0.8 0.8 0.8 1" />
    </material>
    <material name="BlueGrey">
        <color rgba="0.004 0.34 0.61 1.0" />
    </material>
    <material name="Transparent">
        <color rgba="0.0 0.0 0.0 0.0" />
    </material>
    <!-- Base link comprising the board behind the robot and the cylinder at its bottom -->
    <link name="robot_support">
        <visual>
            <geometry>
                <mesh filename="package://lynxmotion_al5d_description/meshes/robot_parts/support.dae" />
            </geometry>
            <origin rpy="0 0 0" xyz="0 0 0" />
        </visual>
        <collision>
            <geometry>
                <mesh filename="package://lynxmotion_al5d_description/meshes/robot_parts/support.dae" />
            </geometry>
            <origin rpy="0 0 0" xyz="0 0 0" />
        </collision>
        <inertial>
            <origin rpy="0 0 0" xyz="0.000585 0.0602746 0.0170628" />
            <mass value="2.3" />
            <inertia ixx="3.6565e-07" ixy="-3.72e-09" ixz="1e-06" iyy="9.404e-08" iyz="4.375e-08" izz="4.1776e-07" />
        </inertial>
    </link>
    <gazebo reference="robot_support" />
    <link name="robot_base_cylinder">
        <visual>
            <geometry>
                <mesh filename="package://lynxmotion_al5d_description/meshes/robot_parts/rotation_cylinder.dae" />
            </geometry>
            <origin rpy="0 0 0" xyz="0 -0.021 0" />
        </visual>
        <collision>
            <geometry>
                <mesh filename="package://lynxmotion_al5d_description/meshes/robot_parts/rotation_cylinder.dae" />
            </geometry>
            <origin rpy="0 0 0" xyz="0 -0.021 0" />
        </collision>
        <inertial>
            <mass value="0.01" />
            <inertia ixx="1.0" ixy="0.0" ixz="0.0" iyy="0.5" iyz="0.0" izz="1.0" />
            <origin xyz="0 0 0" rpy="0 0 0" />
        </inertial>
    </link>
    <gazebo reference="robot_base_cylinder" />
    <link name="robot_base_top_box">
        <visual>
            <geometry>
                <mesh filename="package://lynxmotion_al5d_description/meshes/robot_parts/top_box.dae" />
            </geometry>
            <origin rpy="0 0 3.14159" xyz="-0.01 0.03 0" />
        </visual>
        <collision>
            <geometry>
                <mesh filename="package://lynxmotion_al5d_description/meshes/robot_parts/top_box.dae" />
            </geometry>
            <origin rpy="0 0 3.14159" xyz="-0.01 0.03 0" />
        </collision>
        <inertial>
            <mass value="1" />
            <inertia ixx="1.0" ixy="0.0" ixz="0.0" iyy="0.5" iyz="0.0" izz="1.0" />
            <origin xyz="0 0 0" rpy="0 0 0" />
        </inertial>
    </link>
    <gazebo reference="robot_base_top_box" />
    <link name="shoulder">
        <visual>
            <geometry>
                <mesh filename="package://lynxmotion_al5d_description/meshes/robot_parts/shoulder.dae" />
            </geometry>
            <origin rpy="-1.96349375 0 0" xyz="0.005 -0.0625 0.036" />
        </visual>
        <collision>
            <geometry>
                <mesh filename="package://lynxmotion_al5d_description/meshes/robot_parts/shoulder.dae" />
            </geometry>
            <origin rpy="-1.96349375 0 0" xyz="0.005 -0.0625 0.036" />
        </collision>
        <inertial>
            <mass value="0.5" />
            <inertia ixx="1.0" ixy="0.0" ixz="0.0" iyy="0.5" iyz="0.0" izz="1.0" />
            <origin xyz="0 0 0" rpy="0 0 0" />
        </inertial>
    </link>
    <gazebo reference="shoulder" />
    <link name="elbow">
        <visual>
            <geometry>
                <mesh filename="package://lynxmotion_al5d_description/meshes/robot_parts/elbow.dae" />
            </geometry>
            <origin rpy="-4.03659 3.14159 0" xyz="-0.006 0.13 -0.16399999999999998" />
        </visual>
        <collision>
            <geometry>
                <mesh filename="package://lynxmotion_al5d_description/meshes/robot_parts/elbow.dae" />
            </geometry>
            <origin rpy="-4.03659 3.14159 0" xyz="-0.005 0.135 -0.16599999999999998 " />
        </collision>
        <inertial>
            <mass value="0.16" />
            <inertia ixx="1.0" ixy="0.0" ixz="0.0" iyy="0.5" iyz="0.0" izz="1.0" />
            <origin xyz="0 0 0" rpy="0 0 0" />
        </inertial>
    </link>
    <gazebo reference="elbow" />
    <link name="wrist">
        <visual>
            <geometry>
                <mesh filename="package://lynxmotion_al5d_description/meshes/robot_parts/wrist.dae" />
            </geometry>
            <origin rpy="3.14159 0 0" xyz="0.005 -0.165 0.0695" />
        </visual>
        <collision>
            <geometry>
                <mesh filename="package://lynxmotion_al5d_description/meshes/robot_parts/wrist.dae" />
            </geometry>
            <origin rpy="3.14159 0 0" xyz="0 -0.165 0.067" />
        </collision>
        <inertial>
            <mass value="0.031" />
            <inertia ixx="1.0" ixy="0.0" ixz="0.0" iyy="0.5" iyz="0.0" izz="1.0" />
            <origin xyz="0 0 0" rpy="0 0 0" />
        </inertial>
    </link>
    <gazebo reference="wrist" />
    <link name="gripper">
        <visual>
            <geometry>
                <mesh filename="package://lynxmotion_al5d_description/meshes/robot_parts/gripper.dae" />
            </geometry>
            <origin rpy="1.570795 0 -1.570795" xyz="0 -0.02 0.0" />
        </visual>
        <collision>
            <geometry>
                <mesh filename="package://lynxmotion_al5d_description/meshes/robot_parts/gripper.dae" />
            </geometry>
            <origin rpy="1.570795 0 -1.570795" xyz="0 -0.02 0" />
            <!---0.021 -0.005" /> -->
        </collision>
        <inertial>
            <mass value="0.042" />
            <inertia ixx="1.0" ixy="0.0" ixz="0.0" iyy="0.5" iyz="0.0" izz="1.0" />
            <origin xyz="0 0 0" rpy="0 0 0" />
        </inertial>
    </link>
    <gazebo reference="gripper" />
    <link name="left_finger">
        <visual>
            <geometry>
                <mesh filename="package://lynxmotion_al5d_description/meshes/robot_parts/finger_left.dae" />
            </geometry>
            <origin rpy="1.570795 0 -1.570795" xyz="0.001 -0.005 0" />
        </visual>
        <collision>
            <geometry>
                <mesh filename="package://lynxmotion_al5d_description/meshes/robot_parts/finger_left.dae" />
            </geometry>
            <origin rpy="1.570795 0 -1.570795" xyz="0.001 -0.005 0" />
        </collision>
        <inertial>
            <mass value="0.002" />
            <inertia ixx="1.0" ixy="0.0" ixz="0.0" iyy="0.5" iyz="0.0" izz="1.0" />
            <origin xyz="0 0 0" rpy="0 0 0" />
        </inertial>
    </link>
    <gazebo reference="left_finger" />
    <link name="right_finger">
        <visual>
            <geometry>
                <mesh filename="package://lynxmotion_al5d_description/meshes/robot_parts/finger_right.dae" />
            </geometry>
            <origin rpy="1.570795 0 -1.570795" xyz="-0.003 -0.005 0" />
        </visual>
        <collision>
            <geometry>
                <mesh filename="package://lynxmotion_al5d_description/meshes/robot_parts/finger_right.dae" />
            </geometry>
            <origin rpy="1.570795 0 -1.570795" xyz="-0.003 -0.005 0" />
        </collision>
        <inertial>
            <mass value="0.002" />
            <inertia ixx="1.0" ixy="0.0" ixz="0.0" iyy="0.5" iyz="0.0" izz="1.0" />
            <origin xyz="0 0 0" rpy="0 0 0" />
        </inertial>
    </link>
    <gazebo reference="right_finger" />
    <!-- Dummy link used for the gripper -->
    <link name="gripper_mov">
        <visual>
            <origin rpy="0 0 0" xyz="0 0 0" />
            <geometry>
                <box size="0.01 0.01 0.01" />
            </geometry>
            <material name="transparent">Gazebo/GreyTransparent</material>
        </visual>
        <collision>
            <origin rpy="0 0 0" xyz="0 0 0" />
            <geometry>
                <box size="0.01 0.01 0.01" />
            </geometry>
        </collision>
        <inertial>
            <mass value="0.01" />
            <inertia ixx="1.666666666666667e-07" ixy="0.0" ixz="0.0" iyy="1.666666666666667e-07" iyz="0.0" izz="1.666666666666667e-07" />
            <origin xyz="0 0 0" rpy="0 0 0" />
        </inertial>
    </link>
    <gazebo reference="gripper_mov" />
    <!-- Adding joints -->
    <joint name="Joint1" type="revolute">
        <parent link="robot_support" />
        <child link="robot_base_cylinder" />
        <axis xyz="0 0 -1" />
        <origin rpy="0 0 3.14159" xyz="0 0.02 0" />
        <limit effort="100" lower="-3.14159" upper="3.14159" velocity="3" />
        <dynamics damping="50.0" friction="1" />
    </joint>
    <joint name="base_to_cylinder" type="fixed">
        <parent link="robot_base_cylinder" />
        <child link="robot_base_top_box" />
        <dynamics damping="1.0" friction="0.8" />
    </joint>
    <joint name="Joint2" type="revolute">
        <parent link="robot_base_top_box" />
        <child link="shoulder" />
        <axis xyz="1 0 0" />
        <origin xyz="0 0.02 0.07" />
        <limit effort="100" lower="0" upper="3.14159" velocity="3" />
        <dynamics damping="1.0" friction="0.8" />
    </joint>
    <joint name="Joint3" type="revolute">
        <parent link="shoulder" />
        <child link="elbow" />
        <axis xyz="1 0 0" />
        <origin xyz="0 0.146 0" />
        <limit effort="100" lower="-3.14159" upper="0" velocity="3" />
        <dynamics damping="1.0" friction="0.8" />
    </joint>
    <joint name="Joint4" type="revolute">
        <parent link="elbow" />
        <child link="wrist" />
        <axis xyz="1 0 0" />
        <origin rpy="0 0 0" xyz="0 0.181 0.005" />
        <limit effort="40" lower="-1.570795" upper="1.570795" velocity="3" />
        <dynamics damping="5.0" friction="0.08" />
    </joint>
    <joint name="Joint5" type="revolute">
        <parent link="wrist" />
        <child link="gripper" />
        <axis xyz="0 -1 0" />
        <origin rpy="0 0 3.14159" xyz="0 0.04 0" />
        <limit effort="100" lower="-3.14159" upper="3.14159" velocity="3" />
        <dynamics damping="1.0" friction="0.8" />
    </joint>
    <joint name="right_finger_joint" type="prismatic">
        <parent link="gripper" />
        <child link="right_finger" />
        <origin xyz="-0.005 -0.015 0" />
        <limit effort="100" lower="0" upper="0.015875" velocity="0.1" />
        <mimic joint="Gripper" multiplier="-0.5" offset="0.015875" />
        <dynamics damping="1.0" friction="0.16" />
    </joint>
    <joint name="left_finger_joint" type="prismatic">
        <parent link="gripper" />
        <child link="left_finger" />
        <origin xyz="0.005 -0.015 0" />
        <axis xyz="-1 0 0" />
        <limit effort="100" lower="0" upper="0.015875" velocity="0.1" />
        <!-- Added an offset to fix issues in Rviz -->
        <mimic joint="right_finger_joint" offset="-0.0025" />
        <dynamics damping="1.0" friction="0.16" />
    </joint>
    <!-- Joint that accept the distance between the two fingers as parameter -->
    <joint name="Gripper" type="prismatic">
        <parent link="gripper" />
        <child link="gripper_mov" />
        <origin xyz="0.01 0  0" />
        <limit effort="10" lower="0" upper="0.03175" velocity="0.1" />
        <axis xyz="-1 0 0" />
        <dynamics damping="5.0" />
        <!-- <dynamics friction="0.42" /> -->
    </joint>
    <transmission name="trans_Joint1">
        <type>transmission_interface/SimpleTransmission</type>
        <joint name="Joint1">
            <hardwareInterface>hardware_interface/PositionJointInterface</hardwareInterface>
        </joint>
        <actuator name="Joint1_motor">
            <hardwareInterface>hardware_interface/PositionJointInterface</hardwareInterface>
            <mechanicalReduction>1</mechanicalReduction>
        </actuator>
    </transmission>
    <transmission name="trans_Joint2">
        <type>transmission_interface/SimpleTransmission</type>
        <joint name="Joint2">
            <hardwareInterface>hardware_interface/PositionJointInterface</hardwareInterface>
        </joint>
        <actuator name="Joint2_motor">
            <hardwareInterface>hardware_interface/PositionJointInterface</hardwareInterface>
            <mechanicalReduction>1</mechanicalReduction>
        </actuator>
    </transmission>
    <transmission name="trans_Joint3">
        <type>transmission_interface/SimpleTransmission</type>
        <joint name="Joint3">
            <hardwareInterface>hardware_interface/PositionJointInterface</hardwareInterface>
        </joint>
        <actuator name="Joint3_motor">
            <hardwareInterface>hardware_interface/PositionJointInterface</hardwareInterface>
            <mechanicalReduction>1</mechanicalReduction>
        </actuator>
    </transmission>
    <transmission name="trans_Joint4">
        <type>transmission_interface/SimpleTransmission</type>
        <joint name="Joint4">
            <hardwareInterface>hardware_interface/PositionJointInterface</hardwareInterface>
        </joint>
        <actuator name="Joint4_motor">
            <hardwareInterface>hardware_interface/PositionJointInterface</hardwareInterface>
            <mechanicalReduction>1</mechanicalReduction>
        </actuator>
    </transmission>
    <transmission name="trans_Joint5">
        <type>transmission_interface/SimpleTransmission</type>
        <joint name="Joint5">
            <hardwareInterface>hardware_interface/PositionJointInterface</hardwareInterface>
        </joint>
        <actuator name="Joint5_motor">
            <hardwareInterface>hardware_interface/PositionJointInterface</hardwareInterface>
            <mechanicalReduction>1</mechanicalReduction>
        </actuator>
    </transmission>
    <transmission name="trans_Gripper">
        <type>transmission_interface/SimpleTransmission</type>
        <joint name="Gripper">
            <hardwareInterface>hardware_interface/PositionJointInterface</hardwareInterface>
        </joint>
        <actuator name="Gripper_motor">
            <hardwareInterface>hardware_interface/PositionJointInterface</hardwareInterface>
            <mechanicalReduction>1</mechanicalReduction>
        </actuator>
    </transmission>
    <!-- Load ros_control -->
    <gazebo>
        <plugin name="gazebo_ros_control" filename="libgazebo_ros_control.so">
            <robotNamespace>/</robotNamespace>
        </plugin>
    </gazebo>
</robot>
